<?xml version="1.0"?>

<robot name="my_robot">

  <!-- ================= BASE ================= -->

  <link name="base_link">

    <visual>
      <geometry>
        <box size="0.5 0.3 0.1"/>
      </geometry>

      <material name="blue">
        <color rgba="0 0 1 1"/>
      </material>
    </visual>

    <collision>
      <geometry>
        <box size="0.5 0.3 0.1"/>
      </geometry>
    </collision>

    <inertial>

      <mass value="5.0"/>

      <origin xyz="0 0 0"/>

      <inertia
        ixx="0.1"
        ixy="0.0"
        ixz="0.0"
        iyy="0.1"
        iyz="0.0"
        izz="0.1"/>

    </inertial>

  </link>

  <!-- ================= LEFT WHEEL ================= -->

  <link name="left_wheel">

    <visual>

      <origin xyz="0 0 0" rpy="1.5707 0 0"/>

      <geometry>
        <cylinder radius="0.07" length="0.05"/>
      </geometry>

      <material name="black">
        <color rgba="0 0 0 1"/>
      </material>

    </visual>

    <collision>

      <origin xyz="0 0 0" rpy="1.5707 0 0"/>

      <geometry>
        <cylinder radius="0.07" length="0.05"/>
      </geometry>

    </collision>

    <inertial>

      <mass value="1.0"/>

      <origin xyz="0 0 0"/>

      <inertia
        ixx="0.01"
        ixy="0.0"
        ixz="0.0"
        iyy="0.01"
        iyz="0.0"
        izz="0.01"/>

    </inertial>

  </link>

  <!-- ================= RIGHT WHEEL ================= -->

  <link name="right_wheel">

    <visual>

      <origin xyz="0 0 0" rpy="1.5707 0 0"/>

      <geometry>
        <cylinder radius="0.07" length="0.05"/>
      </geometry>

      <material name="black">
        <color rgba="0 0 0 1"/>
      </material>

    </visual>

    <collision>

      <origin xyz="0 0 0" rpy="1.5707 0 0"/>

      <geometry>
        <cylinder radius="0.07" length="0.05"/>
      </geometry>

    </collision>

    <inertial>

      <mass value="1.0"/>

      <origin xyz="0 0 0"/>

      <inertia
        ixx="0.01"
        ixy="0.0"
        ixz="0.0"
        iyy="0.01"
        iyz="0.0"
        izz="0.01"/>

    </inertial>

  </link>

  <!-- ================= LEFT JOINT ================= -->

  <joint name="left_wheel_joint" type="continuous">

    <parent link="base_link"/>
    <child link="left_wheel"/>

    <origin xyz="0 0.18 0"/>

    <axis xyz="0 1 0"/>

  </joint>

  <!-- ================= RIGHT JOINT ================= -->

  <joint name="right_wheel_joint" type="continuous">

    <parent link="base_link"/>
    <child link="right_wheel"/>

    <origin xyz="0 -0.18 0"/>

    <axis xyz="0 1 0"/>

  </joint>

  <!-- ================= GAZEBO COLORS ================= -->

  <gazebo reference="base_link">
    <material>Gazebo/Blue</material>
  </gazebo>

  <!-- ================= DIFFERENTIAL DRIVE ================= -->

  <gazebo>

    <plugin name="differential_drive_controller"
            filename="libgazebo_ros_diff_drive.so">

      <ros>
        <namespace>/</namespace>
      </ros>

      <left_joint>left_wheel_joint</left_joint>
      <right_joint>right_wheel_joint</right_joint>

      <wheel_separation>0.36</wheel_separation>
      <wheel_diameter>0.14</wheel_diameter>

      <max_wheel_torque>20</max_wheel_torque>
      <max_wheel_acceleration>1.0</max_wheel_acceleration>

      <command_topic>cmd_vel</command_topic>

      <odometry_topic>odom</odometry_topic>

      <odometry_frame>odom</odometry_frame>
      <robot_base_frame>base_link</robot_base_frame>

      <publish_odom>true</publish_odom>
      <publish_odom_tf>true</publish_odom_tf>
      <publish_wheel_tf>true</publish_wheel_tf>

    </plugin>

  </gazebo>

</robot>